Workbook

Sheet Summary
A1: SCAD GIS Gap Assessment – Summary
A2: Live summary driven by the Rating column in the Gap Assessment sheet.
A4: Total Requirements | C4: Assessed | E4: Evidence Items | G4: Overall Maturity
A5: =COUNTA('Gap Assessment'!A7:A51) -> 45 | C5: =COUNTA('Gap Assessment'!H7:H51) -> 16 | E5: =COUNTA('Evidence Register'!A6:A100) -> 3 | G5: =IF(COUNTA('Gap Assessment'!H7:H51)=0,"",(3*COUNTIF('Gap Assessment'!H7:H51,"Established")+2*COUNTIF('Gap Assessment'!H7:H51,"Partially Established")+COUNTIF('Gap Assessment'!H7:H51,"Significant Gap"))/(3*COUNTA('Gap Assessment'!H7:H51))) -> 0.77083333
A9: Domain | B9: Established | C9: Partially Established | D9: Significant Gap | E9: Not Established | F9: Assessed | G9: Total | H9: Maturity %
A10: GIS Field Enumeration & Data Collection | B10: =COUNTIFS('Gap Assessment'!$B$7:$B$51,$A10,'Gap Assessment'!$H$7:$H$51,B$9) -> 3 | C10: =COUNTIFS('Gap Assessment'!$B$7:$B$51,$A10,'Gap Assessment'!$H$7:$H$51,C$9) -> 2 | D10: =COUNTIFS('Gap Assessment'!$B$7:$B$51,$A10,'Gap Assessment'!$H$7:$H$51,D$9) -> 2 | E10: =COUNTIFS('Gap Assessment'!$B$7:$B$51,$A10,'Gap Assessment'!$H$7:$H$51,E$9) -> 0 | F10: =SUM(B10:E10) -> 7 | G10: =COUNTIF('Gap Assessment'!$B$7:$B$51,$A10) -> 7 | H10: =IF(F10=0,"",(3*B10+2*C10+D10)/(3*F10)) -> 0.71428571
A11: Spatial Data Schema Development & Maintenance | B11: =COUNTIFS('Gap Assessment'!$B$7:$B$51,$A11,'Gap Assessment'!$H$7:$H$51,B$9) -> 0 | C11: =COUNTIFS('Gap Assessment'!$B$7:$B$51,$A11,'Gap Assessment'!$H$7:$H$51,C$9) -> 0 | D11: =COUNTIFS('Gap Assessment'!$B$7:$B$51,$A11,'Gap Assessment'!$H$7:$H$51,D$9) -> 0 | E11: =COUNTIFS('Gap Assessment'!$B$7:$B$51,$A11,'Gap Assessment'!$H$7:$H$51,E$9) -> 1 | F11: =SUM(B11:E11) -> 1 | G11: =COUNTIF('Gap Assessment'!$B$7:$B$51,$A11) -> 7 | H11: =IF(F11=0,"",(3*B11+2*C11+D11)/(3*F11)) -> 0
A12: GIS Schema Change Management, Impact Assessment & Periodic Review | B12: =COUNTIFS('Gap Assessment'!$B$7:$B$51,$A12,'Gap Assessment'!$H$7:$H$51,B$9) -> 0 | C12: =COUNTIFS('Gap Assessment'!$B$7:$B$51,$A12,'Gap Assessment'!$H$7:$H$51,C$9) -> 0 | D12: =COUNTIFS('Gap Assessment'!$B$7:$B$51,$A12,'Gap Assessment'!$H$7:$H$51,D$9) -> 0 | E12: =COUNTIFS('Gap Assessment'!$B$7:$B$51,$A12,'Gap Assessment'!$H$7:$H$51,E$9) -> 0 | F12: =SUM(B12:E12) -> 0 | G12: =COUNTIF('Gap Assessment'!$B$7:$B$51,$A12) -> 7 | H12: =IF(F12=0,"",(3*B12+2*C12+D12)/(3*F12))
A13: Geo-Pipeline Operations | B13: =COUNTIFS('Gap Assessment'!$B$7:$B$51,$A13,'Gap Assessment'!$H$7:$H$51,B$9) -> 6 | C13: =COUNTIFS('Gap Assessment'!$B$7:$B$51,$A13,'Gap Assessment'!$H$7:$H$51,C$9) -> 2 | D13: =COUNTIFS('Gap Assessment'!$B$7:$B$51,$A13,'Gap Assessment'!$H$7:$H$51,D$9) -> 0 | E13: =COUNTIFS('Gap Assessment'!$B$7:$B$51,$A13,'Gap Assessment'!$H$7:$H$51,E$9) -> 0 | F13: =SUM(B13:E13) -> 8 | G13: =COUNTIF('Gap Assessment'!$B$7:$B$51,$A13) -> 8 | H13: =IF(F13=0,"",(3*B13+2*C13+D13)/(3*F13)) -> 0.91666667
A14: Enumeration Area (EA) Management | B14: =COUNTIFS('Gap Assessment'!$B$7:$B$51,$A14,'Gap Assessment'!$H$7:$H$51,B$9) -> 0 | C14: =COUNTIFS('Gap Assessment'!$B$7:$B$51,$A14,'Gap Assessment'!$H$7:$H$51,C$9) -> 0 | D14: =COUNTIFS('Gap Assessment'!$B$7:$B$51,$A14,'Gap Assessment'!$H$7:$H$51,D$9) -> 0 | E14: =COUNTIFS('Gap Assessment'!$B$7:$B$51,$A14,'Gap Assessment'!$H$7:$H$51,E$9) -> 0 | F14: =SUM(B14:E14) -> 0 | G14: =COUNTIF('Gap Assessment'!$B$7:$B$51,$A14) -> 8 | H14: =IF(F14=0,"",(3*B14+2*C14+D14)/(3*F14))
A15: GIS Incident Management | B15: =COUNTIFS('Gap Assessment'!$B$7:$B$51,$A15,'Gap Assessment'!$H$7:$H$51,B$9) -> 0 | C15: =COUNTIFS('Gap Assessment'!$B$7:$B$51,$A15,'Gap Assessment'!$H$7:$H$51,C$9) -> 0 | D15: =COUNTIFS('Gap Assessment'!$B$7:$B$51,$A15,'Gap Assessment'!$H$7:$H$51,D$9) -> 0 | E15: =COUNTIFS('Gap Assessment'!$B$7:$B$51,$A15,'Gap Assessment'!$H$7:$H$51,E$9) -> 0 | F15: =SUM(B15:E15) -> 0 | G15: =COUNTIF('Gap Assessment'!$B$7:$B$51,$A15) -> 8 | H15: =IF(F15=0,"",(3*B15+2*C15+D15)/(3*F15))

Sheet Gap Assessment
A1: SCAD GIS – Simple Gap Assessment Matrix
A2: Assessment scope: six GIS operational domains. Use documents, current practice, stakeholder evidence, workflow demonstrations and records.
A3: Important: assessment prompts are adapted from recognized geospatial/service-management practices; they are not verbatim ISO certification clauses.
A6: ID | B6: Domain | C6: Requirement / Control | D6: Assessment Question | E6: Typical Evidence | F6: Evidence Ref(s) | G6: Current Practice / Observation | H6: Rating | I6: Gap / Issue | J6: Recommended Action | K6: Priority
A7: FE-01 | B7: GIS Field Enumeration & Data Collection | C7: Governance, scope and responsibilities | D7: Are the scope, process owner, GIS support role, field team responsibilities, approvals and hand-offs clearly defined for GIS-supported enumeration/data collection? | E7: Approved procedure/work instruction; RACI; role descriptions; organization chart; workshop evidence | F7: Stackholers Meetings | H7: Established | K7: Medium
A8: FE-02 | B8: GIS Field Enumeration & Data Collection | C8: Pre-field spatial preparation | D8: Is there a controlled method to prepare sample locations, reference layers, field maps and geographic identifiers before fieldwork starts? | E8: Sample/location preparation records; map packages; authoritative reference layers; pre-field checklist | F8: Stackholers Meetings | G8: Pre- Field coverd | H8: Established | K8: High
A9: FE-03 | B9: GIS Field Enumeration & Data Collection | C9: Coordinate and reference standards | D9: Are coordinate capture rules, coordinate reference system, precision, geographic identifiers and acceptable location sources standardized and communicated to field teams? | E9: Field specification; CRS standard; device settings; geographic reference guide | F9: Stackholers Meetings | G9: No detailed information | H9: Significant Gap | K9: Low
A10: FE-04 | B10: GIS Field Enumeration & Data Collection | C10: Field capture rules and mandatory attributes | D10: Are required spatial/non-spatial fields, validation rules, coding lists, geometry/location requirements and completeness checks defined for field capture? | E10: Digital form configuration; field schema; validation rules; mandatory-field list; data dictionary | F10: Stackholers Meetings | G10: implemented after received field data. | H10: Significant Gap | I10: Not Covered the field survey proceduers. | K10: Low
A11: FE-05 | B11: GIS Field Enumeration & Data Collection | C11: Field and post-field quality control | D11: Are field and post-field quality checks defined for coordinates, spatial classification, completeness, location consistency and other relevant quality dimensions? | E11: QC checklist; validation report; sample QA results; exception logs; acceptance criteria | F11: Stackholers Meetings | G11: Noinformation yet | H11: Partially Established | I11: No Post-Field Information | J11: Stackholder Meet | K11: High
A12: FE-06 | B12: GIS Field Enumeration & Data Collection | C12: Exceptions, corrections and re-submission | D12: Is there a defined process to flag invalid locations or records, correct them, re-submit data and retain the correction history? | E12: Exception log; correction workflow; re-submission records; audit trail | F12: Stackholers Meetings | G12: Connections with other teams (IT, Methodology) | H12: Partially Established | I12: Need specefic procedurs (Connections Plan) | J12: Stackholder Meet | K12: Medium
A13: FE-07 | B13: GIS Field Enumeration & Data Collection | C13: Handover, traceability and records | D13: Is the handover from field collection to GIS/data processing controlled, with identifiable batches, timestamps, versions, acceptance evidence and retained records? | E13: Handover checklist; batch log; acceptance record; version history; retained field outputs | F13: Stackholers Meetings | H13: Established | K13: High
A14: SD-01 | B14: Spatial Data Schema Development & Maintenance | C14: Business purpose and schema requirements | D14: Is each spatial schema designed from documented business/data requirements, intended use, data product scope and stakeholder needs? | E14: Requirements document; data product specification; stakeholder approvals
A15: SD-02 | B15: Spatial Data Schema Development & Maintenance | C15: Feature, geometry and relationship model | D15: Are feature types, geometry types, attributes, relationships and cardinalities explicitly defined and documented? | E15: Conceptual/logical model; ERD/UML; feature catalogue; schema documentation
A16: SD-03 | B16: Spatial Data Schema Development & Maintenance | C16: Attribute, naming and constraint standards | D16: Are naming conventions, data types, domains/code lists, mandatory fields, uniqueness rules and other constraints standardized? | E16: Schema standards; naming convention; domains/code lists; constraint definitions
A17: SD-04 | B17: Spatial Data Schema Development & Maintenance | C17: Spatial reference and geometry rules | D17: Are coordinate reference systems, precision, geometry validity and relevant topology rules defined for the schema? | E17: CRS specification; geometry rules; topology rules; database constraints | F17: E-001 | G17: The benchmark presentation states WGS 1984, six-digit coordinate precision and spatial/topological checks; operational enforcement evidence is still required. | H17: Not Established | K17: Low
A18: SD-05 | B18: Spatial Data Schema Development & Maintenance | C18: Data dictionary, feature catalogue and metadata linkage | D18: Is the schema supported by a maintained data dictionary/feature catalogue and linked to metadata describing content, lineage, reference system and maintenance? | E18: Data dictionary; feature catalogue; metadata profile; metadata records
A19: SD-06 | B19: Spatial Data Schema Development & Maintenance | C19: Ownership, custodianship and version baseline | D19: Are schema owner/custodian roles, authoritative baseline, version identifiers, effective dates and release history defined? | E19: Ownership matrix; schema register; baseline/version log; approval records
A20: SD-07 | B20: Spatial Data Schema Development & Maintenance | C20: Validation, review and maintenance | D20: Is the schema validated before use and periodically reviewed for obsolete fields, new requirements, quality issues and alignment with dependent systems? | E20: Schema validation results; review minutes; maintenance schedule; issue/change log
A21: CM-01 | B21: GIS Schema Change Management, Impact Assessment & Periodic Review | C21: Formal change request and register | D21: Are schema changes initiated through a controlled request containing requester, reason, affected objects, business need and required date? | E21: Change request form; change register; ticket/request records
A22: CM-02 | B22: GIS Schema Change Management, Impact Assessment & Periodic Review | C22: Change classification and prioritization | D22: Are changes classified (e.g., minor/major/emergency) and prioritized using defined criteria? | E22: Change categories; priority criteria; change register; governance rules
A23: CM-03 | B23: GIS Schema Change Management, Impact Assessment & Periodic Review | C23: Impact assessment | D23: Does each material schema change assess impacts on data, ETL/pipelines, applications, services, metadata, reports, integrations, users and historical compatibility? | E23: Impact assessment template; dependency map; affected-object list; stakeholder comments
A24: CM-04 | B24: GIS Schema Change Management, Impact Assessment & Periodic Review | C24: Review and approval authority | D24: Are review, technical validation and approval roles defined, with authorization appropriate to the change impact? | E24: Approval matrix; RACI; approved change records; meeting minutes
A25: CM-05 | B25: GIS Schema Change Management, Impact Assessment & Periodic Review | C25: Testing and compatibility validation | D25: Are schema changes tested before production, including data validation, dependent workflows/services and backward compatibility where relevant? | E25: Test plan; test results; UAT; regression checks; sample validation
A26: CM-06 | B26: GIS Schema Change Management, Impact Assessment & Periodic Review | C26: Deployment, versioning and communication | D26: Are approved changes released through a controlled deployment with version number, effective date, release notes and communication to affected stakeholders? | E26: Release record; version history; deployment checklist; communications
A27: CM-07 | B27: GIS Schema Change Management, Impact Assessment & Periodic Review | C27: Rollback, post-implementation review and periodic review | D27: Are rollback/recovery arrangements defined, and are implemented changes and the overall schema periodically reviewed for effectiveness and unintended impacts? | E27: Rollback plan; backup evidence; post-implementation review; periodic review schedule/minutes
A28: GP-01 | B28: Geo-Pipeline Operations | C28: Source onboarding and intake controls | D28: Are incoming administrative/spatial datasets registered and checked for source, expected structure, completeness, integrity, timeliness and authorization before processing? | E28: Source register; intake checklist; interface specification; batch receipt log | F28: E-003 | H28: Established | K28: Medium
A29: GP-02 | B29: Geo-Pipeline Operations | C29: Spatial/non-spatial identification and geo-enablement | D29: Is there a defined method to identify spatial versus non-spatial data and geo-enable eligible records using approved geocoding/location references? | E29: Workflow; geocoding rules; match-rate report; exception records | F29: E-001 E-003 | H29: Established | I29: Need mor Deep Explaination | K29: Medium
A30: GP-03 | B30: Geo-Pipeline Operations | C30: Transformation and spatial standardization | D30: Are transformations and standardization rules controlled for geographic classification, coordinates, CRS, formats and other required spatial conventions? | E30: ETL rules; transformation mapping; standardization specification; job configuration | F30: E-001 E-003 | H30: Partially Established | I30: No Standardization | K30: High
A31: GP-04 | B31: Geo-Pipeline Operations | C31: Data quality gates | D31: Are measurable quality gates applied before ingestion/publishing for topology, completeness, positional/thematic/temporal quality, coverage and attribute consistency as applicable? | E31: Quality rules; thresholds; validation reports; rejected-record log; quality results | F31: E-001 E-003 | H31: Established | K31: High
A32: GP-05 | B32: Geo-Pipeline Operations | C32: Metadata and lineage | D32: Is metadata created/updated at defined pipeline checkpoints, including identification, extent, quality, lineage, spatial reference, distribution, maintenance and responsibility? | E32: Metadata template/profile; metadata records; lineage records; metadata validation | F32: E-001 E-003 | H32: Established | K32: High
A33: GP-06 | B33: Geo-Pipeline Operations | C33: Ingestion, storage and post-ingestion validation | D33: Are database ingestion/storage steps controlled and followed by reconciliation or post-ingestion validation to confirm completeness and consistency with the processed input? | E33: Load logs; reconciliation totals; database validation report; failed-load records | F33: E-001 E-003 | H33: Established | K33: High
A34: GP-07 | B34: Geo-Pipeline Operations | C34: Publishing and service release controls | D34: Are datasets/services published only after approval and validation, with controlled target environments, access settings, version/release information and traceability? | E34: Publishing checklist; approval record; service catalogue; release record; access configuration | F34: E-001 E-003 | H34: Established | K34: High
A35: GP-08 | B35: Geo-Pipeline Operations | C35: Monitoring, exceptions and reprocessing | D35: Are pipeline jobs and published outputs monitored, with defined alerts, exception handling, reprocessing, escalation and retained operational logs? | E35: Monitoring dashboard; job logs; alert records; exception/reprocessing log; escalation records | F35: E-003 | H35: Partially Established | I35: Need more clear Explaination | K35: Medium
A36: EA-01 | B36: Enumeration Area (EA) Management | C36: EA design criteria and governance | D36: Are documented criteria defined for EA purpose, coverage, size/workload, contiguity, non-overlap, boundary selection and governance responsibilities? | E36: EA design standard; methodology; governance roles; approved criteria
A37: EA-02 | B37: Enumeration Area (EA) Management | C37: Authoritative reference data and hierarchy | D37: Are authoritative administrative boundaries, buildings/addresses, roads and other reference layers identified for EA creation and maintenance? | E37: Reference data register; source agreements; authoritative layer list; update schedule
A38: EA-03 | B38: Enumeration Area (EA) Management | C38: Creation, identifiers and versioning | D38: Are EAs created using consistent rules with unique identifiers, hierarchy relationships, version/effective dates and reproducible delineation records? | E38: EA geodatabase; identifier rules; version log; creation records
A39: EA-04 | B39: Enumeration Area (EA) Management | C39: Spatial and statistical validation | D39: Are EAs validated for gaps/overlaps, topology, coverage, population/building/address linkage and other agreed thresholds before use? | E39: Topology report; coverage report; linkage statistics; validation checklist
A40: EA-05 | B40: Enumeration Area (EA) Management | C40: Linkage to surveys, census and registers | D40: Is there a controlled method to link the correct EA version to surveys, census operations, registers and sampling frames, with traceable identifiers? | E40: Survey/EA crosswalk; sampling frame; register linkage; version reference
A41: EA-06 | B41: Enumeration Area (EA) Management | C41: EA updates and change history | D41: Are EA updates triggered, assessed, approved and recorded with reasons, affected areas, effective dates and historical versions retained? | E41: EA change request; approval; change log; archived versions; change map
A42: EA-07 | B42: Enumeration Area (EA) Management | C42: Field verification and reconciliation | D42: Where field verification is required, are boundary/location discrepancies captured, reviewed and reconciled before updating the authoritative EA layer? | E42: Field verification records; discrepancy log; reconciliation decisions; updated EA evidence
...

Sheet Evidence Register
A1: Evidence Register
A2: Register SCAD operational evidence once, assign an Evidence ID, then reference that ID in the Gap Assessment matrix.
A5: Evidence ID | B5: Evidence Name | C5: Type | D5: Date / Version | E5: Owner / Source | F5: Related Domain(s) | G5: Coverage / Relevance | H5: Received? | I5: Review Notes
A6: E-001 | B6: GIS Benchmark - GeoPipeline.pptx | C6: Presentation | D6: May 2025 | E6: SCAD – Data Products & Engineering | F6: Spatial Data Schema Development & Maintenance; Geo-Pipeline Operations | G6: Spatial Data Journey; geocoding; geographic classification; WGS 1984 and coordinate precision; spatial quality checks; ISO 19115 metadata; ISO 19157 data quality; ESDM; ArcGIS Enterprise / Geostatistical Platform. | H6: Yes | I6: Initial concept-level evidence only. It describes practices/concepts but does not by itself confirm controlled SOPs, approvals, operating records, monitoring logs or consistent implementation.
A7: E-002 | B7: ISO 19115 7& ISO 19157 SOPs | C7: SOPs | E7: GIS Section | H7: No
A8: E-003 | B8: Geo-Pipline Tracking Sheet | C8: Form | E8: GIS Section | F8: Geo-Pipeline Operations; Spatial Data Schema; Field Enumeration & Data Collection | G8: Geo-Pipline Journy | H8: Yes

Sheet Guidance & Sources
A1: Assessment Guidance & Best-Practice Sources
A3: Rating | B3: Definition | C3: Score
A4: Established | B4: Requirement/process is clearly defined and consistently implemented. | C4: 3
A5: Partially Established | B5: Practice exists but requires clarification or improvement. | C5: 2
A6: Significant Gap | B6: Major elements are missing or inconsistently implemented. | C6: 1
A7: Not Established | B7: No defined/documented practice or control exists. | C7: 0
A10: Project Rating Notes
A11: Activity exists but no controlled SOP | B11: Normally treat as Significant Gap, subject to impact and consistency.
A12: Document exists but is not governed/approved | B12: Treat as Partially Established or Significant Gap depending on impact.
