Workbook

Sheet Request Tracker
A1: SCAD GIS – Evidence Request & Tracking List
A2: Purpose: request, track and review evidence for the six GIS domains. Legacy ISO 19115/19157 documents are treated as supporting evidence only until current practice is validated.
A3: Total Requests | B3: 49 | C3: Current / Known Evidence | D3: 40 | E3: To Request | F3: 9 | G3: Critical | H3: 31
A5: Request ID | B5: Domain | C5: Evidence Group | D5: Evidence / Information Requested | E5: Examples / Minimum Expected | F5: Assessment Purpose | G5: Priority | H5: Known Existing / Legacy Reference | I5: Tracking Status | J5: SCAD Owner | K5: Request Date | L5: Target Date | M5: Received Date | N5: Received File / Ref | O5: Review Result | P5: Review Notes / Gap Ref
A6: GOV-01 | B6: All Domains / Cross-cutting | C6: Governance & Roles | D6: Current GIS organization structure, role descriptions and responsibility assignments. | E6: GIS team structure; RACI or responsibility matrix | F6: Confirm process ownership, segregation of duties, approvers, reviewers and escalation roles. | G6: Critical | I6: Partially Received | K6: 46253 | L6: 46258 | O6: Needs Clarification
A7: GOV-02 | B7: All Domains / Cross-cutting | C7: Controlled Documentation | D7: All GIS policies, SOPs, work instructions, flowcharts and informal operating guides currently used. | F7: Establish the real operating baseline and avoid recreating practices that already exist. | G7: Critical | H7: Legacy ISO 19115/19157 Old package | I7: To Request | K7: 46253 | L7: 46258 | O7: Not Reviewed
A8: GOV-03 | B8: All Domains / Cross-cutting | C8: Document Control | D8: Evidence of document approval, version control, review cycle and change history for GIS documents. | E8: Approval pages, revision history, master document register, review records. | F8: Determine whether operating documents are controlled, current and auditable. | G8: High | H8: Legacy ISO 19115/19157 Old package | I8: To Request | K8: 46253 | L8: 46258 | O8: Not Reviewed
A9: GOV-04 | B9: All Domains / Cross-cutting | C9: Standards & Data Governance | D9: Current GIS standards, data dictionary, terminology, naming/coding rules and metadata/data quality rules. | E9: Data dictionary; coding standards; naming conventions; data quality plan; metadata profile. | F9: Confirm common standards used across the six domains. | G9: Critical | H9: Legacy ISO 19115/19157 Old package | I9: To Request | K9: 46253 | L9: 46258 | O9: Not Reviewed
A10: GOV-05 | B10: All Domains / Cross-cutting | C10: Systems & Interfaces | D10: Current GIS systems, repositories, tools and key interfaces used by the six domains. | E10: System/application list and purpose; ArcGIS Enterprise, ESDM, FME/Informatica, AXON and other relevant tools/interfaces. | F10: Identify system handoffs, control points, repositories and dependencies. | G10: Critical | H10: GIS Benchmark - GeoPipeline.pptx - AXON / GIS tools | I10: To Request | K10: 46253 | L10: 46258 | O10: Not Reviewed
A11: GOV-06 | B11: All Domains / Cross-cutting | C11: Assurance & Improvement | D11: GIS-related audit findings, nonconformities, corrective actions and improvement records. | E11: Audit plans/reports; NC/CAPA records; recurring issues and status. | F11: Assess whether weaknesses are identified, corrected and followed through. | G11: High | H11: Legacy ISO 19115/19157 Old package | I11: To Request | K11: 46253 | L11: 46258 | O11: Not Reviewed
A12: GOV-07 | B12: All Domains / Cross-cutting | C12: Competency | D12: Training, competency and onboarding records for staff performing GIS operational activities. | E12: Training plan; attendance/training reports; competency matrix or role qualification evidence. | F12: Confirm that critical activities are assigned to competent personnel. | G12: Medium | H12: Legacy ISO 19115/19157 Old package | I12: To Request | K12: 46253 | L12: 46258 | O12: Not Reviewed
A13: FDC-01 | B13: GIS Field Enumeration & Data Collection | C13: Current Workflow | D13: Current end-to-end field enumeration and spatial data collection workflow. | E13: Pre-field preparation → field assignment → capture → synchronization → post-field validation → handover. | F13: Validate the actual process, roles, handoffs and decision points. | G13: Critical | I13: Partially Received | K13: 46253 | L13: 46258 | O13: Not Reviewed
A14: FDC-02 | B14: GIS Field Enumeration & Data Collection | C14: Pre-field Preparation | D14: Evidence used to prepare sample locations, field maps, geographic references and assignments. | E14: Sample/location files; map packages; EA/sample references; assignment lists; pre-field checklists. | F14: Assess readiness, completeness and consistency before field deployment. | G14: Critical | H14: Legacy ISO 19115/19157 Old package | I14: Partially Received | K14: 46253 | L14: 46258 | O14: Not Reviewed
A15: FDC-03 | B15: GIS Field Enumeration & Data Collection | C15: Capture Rules & Configuration | D15: Field data model, mandatory attributes, coordinate capture rules and mobile/app/device configuration. | E15: Forms/schema; mandatory fields; CRS; precision; offline/sync settings; validation rules. | F15: Confirm that field capture is standardized and technically controlled. | G15: Critical | H15: Legacy ISO 19115/19157 Old package | I15: To Request | K15: 46253 | L15: 46258 | O15: Not Reviewed
A16: FDC-04 | B16: GIS Field Enumeration & Data Collection | C16: Field QA/QC | D16: Pre-field and in-field quality checks and acceptance criteria. | E16: Checklists; duplicate/missing record checks; coordinate/location checks; supervisor review criteria. | F16: Determine whether quality is prevented/detected at source rather than only after collection. | G16: High | H16: Legacy ISO 19115/19157 Old package | I16: To Request | K16: 46253 | L16: 46258 | O16: Not Reviewed
A17: FDC-05 | B17: GIS Field Enumeration & Data Collection | C17: Sample Execution Records | D17: One or more completed field data collection cases with traceability. | E17: Raw/collected record; timestamps; user/device ID; location; update history; supervisor acceptance. | F17: Verify that the documented/current practice is actually executed and traceable. | G17: Critical | I17: Partially Received | K17: 46253 | L17: 46258 | O17: Not Reviewed
A18: FDC-06 | B18: GIS Field Enumeration & Data Collection | C18: Exceptions & Rework | D18: Field errors, rejected submissions, correction/rework and escalation records. | E18: Error lists; rejected records; issue logs; rework requests; escalation emails/tickets. | F18: Assess exception handling and evidence of resolution. | G18: High | H18: Legacy ISO 19115/19157 Old package | I18: To Request | K18: 46253 | L18: 46258 | O18: Not Reviewed
A19: FDC-07 | B19: GIS Field Enumeration & Data Collection | C19: Post-field Validation & Handover | D19: Post-field X/Y validation, spatial classification checks, acceptance and handover evidence. | E19: Coordinate validation; Region/District/Community checks; final QA report; handover/acceptance record. | F19: Confirm controlled transition from field output to trusted GIS/statistical data. | G19: Critical | H19: Legacy ISO 19115/19157 Old package | I19: To Request | K19: 46253 | L19: 46258 | O19: Not Reviewed
A20: SDS-01 | B20: Spatial Data Schema Development & Maintenance | C20: Schema Baseline | D20: Current geodatabase/data schema models for key spatial datasets. | E20: ERD/UML/geodatabase schema; feature classes/tables; relationships; current baseline/version. | F20: Establish the current technical schema baseline. | G20: Critical | I20: To Request | K20: 46253 | L20: 46258 | O20: Not Reviewed
A21: SDS-02 | B21: Spatial Data Schema Development & Maintenance | C21: Feature & Attribute Catalogue | D21: Feature catalogue/data dictionary with attributes, data types, domains, subtypes and code lists. | E21: Feature/attribute definitions; allowed values; keys; nullability; descriptions; business meaning. | F21: Assess whether schema definitions are standardized and understandable. | G21: Critical | H21: Legacy ISO 19115/19157 Old package | I21: To Request | K21: 46253 | L21: 46258 | O21: Not Reviewed
A22: SDS-03 | B22: Spatial Data Schema Development & Maintenance | C22: Schema Rules | D22: Naming conventions, field rules, identifiers, keys, default values and integrity constraints. | E22: Naming/coding standard; unique ID rules; domains/ranges; mandatory fields; reference tables. | F22: Confirm consistency and integrity across datasets. | G22: High | H22: Legacy ISO 19115/19157 Old package | I22: To Request | K22: 46253 | L22: 46258 | O22: Not Reviewed
A23: SDS-04 | B23: Spatial Data Schema Development & Maintenance | C23: Spatial Model Rules | D23: Geometry, CRS/spatial reference, precision/resolution and topology/relationship rules. | E23: Geometry types; WGS 1984 or other approved CRS; coordinate precision; topology and relationship rules. | F23: Confirm that the spatial model has explicit, testable rules. | G23: Critical | H23: GIS Benchmark - GeoPipeline.pptx | I23: To Request | K23: 46253 | L23: 46258 | O23: Not Reviewed
A24: SDS-05 | B24: Spatial Data Schema Development & Maintenance | C24: Ownership & Approval | D24: Schema ownership, custodianship, review and approval responsibilities. | E24: Schema/data owner list; custodian; technical reviewer; approver; RACI. | F24: Establish accountability for design and maintenance decisions. | G24: Critical | H24: Legacy ISO 19115/19157 Old package | I24: To Request | K24: 46253 | L24: 46258 | O24: Not Reviewed
A25: SDS-06 | B25: Spatial Data Schema Development & Maintenance | C25: Lifecycle & Versioning | D25: Schema baseline, version history, release notes and periodic maintenance/review evidence. | E25: Version register; release notes; review schedule; deprecated elements; maintenance history. | F25: Assess whether schema evolution is controlled and traceable. | G25: High | H25: Legacy ISO 19115/19157 Old package | I25: To Request | K25: 46253 | L25: 46258 | O25: Not Reviewed
A26: SDS-07 | B26: Spatial Data Schema Development & Maintenance | C26: Validation & Metadata | D26: Schema validation/test evidence and link to metadata/lineage. | E26: Schema validation results; test data; metadata records; lineage; product specification if available. | F26: Confirm that schemas are verified and datasets remain discoverable/traceable. | G26: High | H26: Legacy ISO 19115/19157 Old package | I26: To Request | K26: 46253 | L26: 46258 | O26: Not Reviewed
A27: SCM-01 | B27: GIS Schema Change Management | C27: Change Request & Register | D27: Current schema change request mechanism and change register. | E27: Request form; change ID; requester; reason; affected schema/version; status; approvals. | F27: Confirm formal initiation and traceability of changes. | G27: Critical | H27: Legacy ISO 19115/19157 Old package | I27: To Request | K27: 46253 | L27: 46258 | O27: Not Reviewed
A28: SCM-02 | B28: GIS Schema Change Management | C28: Impact Assessment | D28: Impact assessment criteria and completed examples for schema changes. | E28: Impact on datasets, ETL/pipelines, services, apps, metadata, statistics, interfaces and users. | F28: Verify that downstream impacts are assessed before approval. | G28: Critical | H28: Legacy ISO 19115/19157 Old package | I28: To Request | K28: 46253 | L28: 46258 | O28: Not Reviewed
A29: SCM-03 | B29: GIS Schema Change Management | C29: Review & Approval | D29: Governance for reviewing, approving, rejecting and prioritizing schema changes. | E29: Approval matrix; CAB or equivalent; decision record; emergency/standard change route if used. | F29: Confirm decision authority and objective approval criteria. | G29: Critical | H29: Legacy ISO 19115/19157 Old package | I29: To Request | K29: 46253 | L29: 46258 | O29: Not Reviewed
A30: SCM-04 | B30: GIS Schema Change Management | C30: Testing & Acceptance | D30: Testing/UAT/validation records and acceptance criteria before deployment. | E30: Test plan/results; regression/compatibility checks; data validation; user acceptance where relevant. | F30: Reduce risk of breaking dependent data, services or statistical outputs. | G30: High | H30: Legacy ISO 19115/19157 Old package | I30: To Request | K30: 46253 | L30: 46258 | O30: Not Reviewed
A31: SCM-05 | B31: GIS Schema Change Management | C31: Implementation & Communication | D31: Implementation plan, versioning/release notes and stakeholder communication. | E31: Implementation tasks/date/owner; release notes; updated documentation; communication evidence. | F31: Confirm controlled implementation and awareness of affected stakeholders. | G31: High | H31: Legacy ISO 19115/19157 Old package | I31: To Request | K31: 46253 | L31: 46258 | O31: Not Reviewed
A32: SCM-06 | B32: GIS Schema Change Management | C32: Rollback / Backout | D32: Rollback, backup or backout arrangements for unsuccessful schema changes. | E32: Rollback steps; backup/snapshot; restore criteria; decision authority; example if available. | F32: Confirm reversibility of high-impact changes. | G32: Critical | I32: To Request | K32: 46253 | L32: 46258 | O32: Not Reviewed
A33: SCM-07 | B33: GIS Schema Change Management | C33: Post-change & Periodic Review | D33: Post-implementation review and periodic schema review evidence. | E33: PIR record; outcome; unresolved issues; next review date; periodic schema health/relevance review. | F33: Verify closure, learning and ongoing suitability of the schema. | G33: High | H33: Legacy ISO 19115/19157 Old package | I33: To Request | K33: 46253 | L33: 46258 | O33: Not Reviewed
A34: GEO-01 | B34: Geo-Pipeline Operations | C34: Current Workflow | D34: Current end-to-end geo-pipeline workflow and operational ownership. | E34: Receive → integrity check → spatial/non-spatial → geo-enable → standardize → quality → metadata → ingest → validate → publish → monitor. | F34: Validate the pipeline that will become the operational SOP. | G34: Critical | H34: GIS Benchmark - GeoPipeline.pptx Geo-Pipline Tracking Sheet.xlsx | I34: Received | K34: 46253 | L34: 46258 | O34: Not Reviewed
A35: GEO-02 | B35: Geo-Pipeline Operations | C35: Inputs & Source Controls | D35: Data source/provider inventory and input/interface specifications. | E35: Provider/source; format; frequency; delivery channel; required fields; ownership; expected completeness/quality. | F35: Confirm controlled and repeatable ingestion inputs. | G35: High | H35: Geo-Pipline Tracking Sheet.xlsx | I35: Received | K35: 46253 | L35: 46258 | O35: Not Reviewed
A36: GEO-03 | B36: Geo-Pipeline Operations | C36: ETL / Job Configuration | D36: ETL scripts/workflows, schedules, transformation mappings and job configuration. | E36: FME/Informatica/scripts/jobs; schedules; mapping specs; parameter files; job ownership. | F36: Understand automated/manual transformation logic and operational dependencies. | G36: Critical | H36: Legacy ISO 19115/19157 Old package Geo-Pipline Tracking Sheet.xlsx | I36: Partially Received | K36: 46253 | L36: 46258 | O36: Not Reviewed | P36: to be in the GuideLine
A37: GEO-04 | B37: Geo-Pipeline Operations | C37: Geo-enable & Standardization | D37: Geocoding, coordinate assignment, classification, CRS and standardization rules. | E37: Geocoding method; Region/District/Community classification; WGS 1984; coordinate precision; transformation rules. | F37: Confirm consistent location enablement and spatial standardization. | G37: Critical | H37: GIS Benchmark - GeoPipeline.pptx Geo-Pipline Tracking Sheet.xlsx | I37: Partially Received | K37: 46253 | L37: 46258 | O37: Not Reviewed | P37: to be in the GuideLine
A38: GEO-05 | B38: Geo-Pipeline Operations | C38: Quality & Metadata Gates | D38: Operational quality gates, thresholds, data quality reports and metadata/lineage records. | E38: Topology/completeness/temporal/attribute checks; pass/fail thresholds; DQ report; metadata record; lineage. | F38: Determine whether quality and metadata are embedded as pipeline checkpoints. | G38: Critical | H38: Legacy ISO 19115/19157 Old package Geo-Pipline Tracking Sheet.xlsx | I38: Received | K38: 46253 | L38: 46258 | O38: Not Reviewed
A39: GEO-06 | B39: Geo-Pipeline Operations | C39: Database & Publishing Controls | D39: Database ingestion, post-ingestion validation, publishing approval and service configuration. | E39: Load logs; target DB/ESDM mapping; reconciliation; ArcGIS service publishing; approval; access settings. | F39: Confirm controlled release of trusted spatial data/services. | G39: Critical | H39: Legacy ISO 19115/19157 Old package Geo-Pipline Tracking Sheet.xlsx | I39: Received | K39: 46253 | L39: 46258 | O39: Not Reviewed
A40: GEO-07 | B40: Geo-Pipeline Operations | C40: Monitoring, Exceptions & Run Evidence | D40: Pipeline monitoring, job/error logs, alerts, exception/reprocessing records and one completed end-to-end run. | E40: Monitoring dashboard/logs; failed jobs; error reasons; re-run/reprocess evidence; timestamps; final published output. | F40: Verify operational continuity, traceability and evidence of exception handling. | G40: Critical | H40: Legacy ISO 19115/19157 Old package Geo-Pipline Tracking Sheet.xlsx | I40: Requested | K40: 46253 | L40: 46258 | O40: Not Reviewed
A41: EA-01 | B41: Enumeration Area (EA) Management | C41: EA Model & Methodology | D41: Current EA data model, hierarchy, coding and delineation methodology. | E41: EA schema; unique IDs/codes; hierarchy; delineation rules; workload/population/geographic criteria used by SCAD. | F41: Establish the authoritative EA management basis. | G41: Critical | H41: Legacy ISO 19115/19157 Old package | I41: Requested | K41: 46253 | L41: 46258 | O41: Not Reviewed
...

Sheet Existing Evidence
A1: Existing Evidence Inventory – Current + Legacy Files
A5: Evidence ID | B5: Source | C5: Level / Folder | D5: Document Code | E5: Document / File Name | F5: File Type | G5: Master List Description | H5: Master List Status | I5: Working Status | J5: Mapped Domain(s)
A6: CE-001 | B6: Current evidence received | C6: Current project evidence | E6: GIS Benchmark - GeoPipeline.pptx | F6: PPTX | G6: SCAD spatial data journey, quality/metadata concepts, ESDM and ArcGIS Enterprise context. | I6: Current Evidence – Received | J6: Geo-Pipeline Operations; Spatial Data Schema; Field Enumeration & Data Collection
A7: LE-001 | B7: Legacy ISO 19115/19157 Old package | E7: Many | G7: ISO 19115 ISO 19157 | H7: Old | I7: Legacy / Unapproved – In Practice (validate)
A8: E-003 | B8: Geo-Pipline Tracking Sheet | C8: file | E8: Geo-Pipline Tracking Sheet.xlsx | F8: XLSX | H8: Current | I8: Current Evidence – Received | J8: Geo-Pipeline Operations; Spatial Data Schema; Field Enumeration & Data Collection

Sheet Domain Coverage
A1: Domain Coverage & Initial Assessment Plan
A2: Use this sheet to see where evidence already exists and where SCAD needs to provide direct operational evidence. | H2: Total Requests | I2: 49
H3: Known / Current | I3: 40
A4: Domain | B4: Core Requirement Areas | C4: Request Count | D4: Known / Current Evidence | E4: To Request | F4: Recommended First Validation | H4: To Request | I4: 9
A5: All Domains / Cross-cutting | B5: Governance, roles, controlled documents, systems, assurance, competency | C5: =COUNTIF('Request Tracker'!$B$6:$B$200,A5) -> 7 | D5: =COUNTIFS('Request Tracker'!$B$6:$B$200,A5,'Request Tracker'!$I$6:$I$200,"<>To Request") -> 1 | E5: =COUNTIFS('Request Tracker'!$B$6:$B$200,A5,'Request Tracker'!$I$6:$I$200,"To Request") -> 6 | F5: Confirm GIS organization, document set, systems and owners before domain workshops. | H5: Legacy Files Inventoried | I5: 40
A6: GIS Field Enumeration & Data Collection | B6: Field preparation, capture controls, QA/QC, execution records, exceptions, handover | C6: =COUNTIF('Request Tracker'!$B$6:$B$200,A6) -> 7 | D6: =COUNTIFS('Request Tracker'!$B$6:$B$200,A6,'Request Tracker'!$I$6:$I$200,"<>To Request") -> 3 | E6: =COUNTIFS('Request Tracker'!$B$6:$B$200,A6,'Request Tracker'!$I$6:$I$200,"To Request") -> 4 | F6: Walk through one real field collection case from sample/location preparation to accepted output.
A7: Spatial Data Schema Development & Maintenance | B7: Schema baseline, feature/attribute catalogue, spatial rules, ownership, lifecycle, validation | C7: =COUNTIF('Request Tracker'!$B$6:$B$200,A7) -> 7 | D7: =COUNTIFS('Request Tracker'!$B$6:$B$200,A7,'Request Tracker'!$I$6:$I$200,"<>To Request") -> 0 | E7: =COUNTIFS('Request Tracker'!$B$6:$B$200,A7,'Request Tracker'!$I$6:$I$200,"To Request") -> 7 | F7: Review one active geodatabase/schema and its dictionary/ownership/version history.
A8: GIS Schema Change Management | B8: Request, impact, approval, testing, implementation, rollback, post-review | C8: =COUNTIF('Request Tracker'!$B$6:$B$200,A8) -> 7 | D8: =COUNTIFS('Request Tracker'!$B$6:$B$200,A8,'Request Tracker'!$I$6:$I$200,"<>To Request") -> 0 | E8: =COUNTIFS('Request Tracker'!$B$6:$B$200,A8,'Request Tracker'!$I$6:$I$200,"To Request") -> 7 | F8: Walk through one real schema change from request to deployment and review.
A9: Geo-Pipeline Operations | B9: Inputs, ETL, geo-enable, standards, quality/metadata, ingestion/publishing, monitoring | C9: =COUNTIF('Request Tracker'!$B$6:$B$200,A9) -> 7 | D9: =COUNTIFS('Request Tracker'!$B$6:$B$200,A9,'Request Tracker'!$I$6:$I$200,"<>To Request") -> 7 | E9: =COUNTIFS('Request Tracker'!$B$6:$B$200,A9,'Request Tracker'!$I$6:$I$200,"To Request") -> 0 | F9: Demonstrate one recent dataset through the full geo-pipeline end-to-end.
A10: Enumeration Area (EA) Management | B10: EA model/delineation, sources, versioning, QA, statistical linkage, updates, publication | C10: =COUNTIF('Request Tracker'!$B$6:$B$200,A10) -> 7 | D10: =COUNTIFS('Request Tracker'!$B$6:$B$200,A10,'Request Tracker'!$I$6:$I$200,"<>To Request") -> 7 | E10: =COUNTIFS('Request Tracker'!$B$6:$B$200,A10,'Request Tracker'!$I$6:$I$200,"To Request") -> 0 | F10: Review one EA creation/update case with QA and survey/register linkage.
A11: GIS Incident Management | B11: Logging, severity, ownership, response, communication, RCA/CAPA, closure/KPIs | C11: =COUNTIF('Request Tracker'!$B$6:$B$200,A11) -> 7 | D11: =COUNTIFS('Request Tracker'!$B$6:$B$200,A11,'Request Tracker'!$I$6:$I$200,"<>To Request") -> 7 | E11: =COUNTIFS('Request Tracker'!$B$6:$B$200,A11,'Request Tracker'!$I$6:$I$200,"To Request") -> 0 | F11: Review one recent GIS/data/service incident or equivalent issue from detection to closure.
